Traceback (most recent call last):
  File "/opt/hostedtoolcache/Python/3.10.8/x64/lib/python3.10/site-packages/jupyter_cache/executors/utils.py", line 51, in single_nb_execution
    executenb(
  File "/opt/hostedtoolcache/Python/3.10.8/x64/lib/python3.10/site-packages/nbclient/client.py", line 1204, in execute
    return NotebookClient(nb=nb, resources=resources, km=km, **kwargs).execute()
  File "/opt/hostedtoolcache/Python/3.10.8/x64/lib/python3.10/site-packages/nbclient/util.py", line 84, in wrapped
    return just_run(coro(*args, **kwargs))
  File "/opt/hostedtoolcache/Python/3.10.8/x64/lib/python3.10/site-packages/nbclient/util.py", line 62, in just_run
    return loop.run_until_complete(coro)
  File "/opt/hostedtoolcache/Python/3.10.8/x64/lib/python3.10/asyncio/base_events.py", line 649, in run_until_complete
    return future.result()
  File "/opt/hostedtoolcache/Python/3.10.8/x64/lib/python3.10/site-packages/nbclient/client.py", line 663, in async_execute
    await self.async_execute_cell(
  File "/opt/hostedtoolcache/Python/3.10.8/x64/lib/python3.10/site-packages/nbclient/client.py", line 965, in async_execute_cell
    await self._check_raise_for_error(cell, cell_index, exec_reply)
  File "/opt/hostedtoolcache/Python/3.10.8/x64/lib/python3.10/site-packages/nbclient/client.py", line 862, in _check_raise_for_error
    raise CellExecutionError.from_cell_and_msg(cell, exec_reply_content)
nbclient.exceptions.CellExecutionError: An error occurred while executing the following cell:
------------------
from cvedata.winbindex import get_winbindex_desc_to_bin_map, WINBINDEX_GITHUB_URL, get_winbindex_kbs_to_bin_map
from cvedata.win_verinfo import get_verinfo_desc_to_bins_json
from cvedata.msrc_pandas import get_msrc_tags, get_msrc_titles, get_msrc_cvrf_pandas_df, MSRC_CVRF_PANDAS_FULL,MSRC_CVRF_PANDAS
from cvedata.msrc_known_bins import KNOWN_TAG_TO_BIN_MAP
from cvedata.ms_feed_kbs import get_ms_kb_feeds_json,get_ms_kb_feed_files_json,get_ms_kb_to_bins_json


from cvedata.msrc_pandas import clean_impact
from cvedata.msrc_cve_to_bins import clean_tag

pd.set_option('display.max_rows', 15)


------------------

[0;31m---------------------------------------------------------------------------[0m
[0;31mModuleNotFoundError[0m                       Traceback (most recent call last)
Cell [0;32mIn [1], line 9[0m
[1;32m      5[0m [38;5;28;01mfrom[39;00m [38;5;21;01mcvedata[39;00m[38;5;21;01m.[39;00m[38;5;21;01mms_feed_kbs[39;00m [38;5;28;01mimport[39;00m get_ms_kb_feeds_json,get_ms_kb_feed_files_json,get_ms_kb_to_bins_json
[1;32m      8[0m [38;5;28;01mfrom[39;00m [38;5;21;01mcvedata[39;00m[38;5;21;01m.[39;00m[38;5;21;01mmsrc_pandas[39;00m [38;5;28;01mimport[39;00m clean_impact
[0;32m----> 9[0m [38;5;28;01mfrom[39;00m [38;5;21;01mcvedata[39;00m[38;5;21;01m.[39;00m[38;5;21;01mmsrc_cve_to_bins[39;00m [38;5;28;01mimport[39;00m clean_tag
[1;32m     11[0m pd[38;5;241m.[39mset_option([38;5;124m'[39m[38;5;124mdisplay.max_rows[39m[38;5;124m'[39m, [38;5;241m15[39m)

[0;31mModuleNotFoundError[0m: No module named 'cvedata.msrc_cve_to_bins'
ModuleNotFoundError: No module named 'cvedata.msrc_cve_to_bins'

